Workbook

Sheet 1o
A1: No | B1: Dirección de correo electrónico | C1: CURSO | D1: PARALELO | E1: Apellidos del Estudiante | F1: Nombres del Estudiante | G1: M | H1: F | I1: Número de Cédula del Estudiante | J1: Fecha de Nacimiento del estudiante | K1: Edad | L1: Apellidos del Representante del Estudiante | M1: Nombres del Representante del Estudiante | N1: Número de cédula del Representante | O1: Dirección | P1: Número telefónico convencional | Q1: Número telefónico celular 1 | R1: Número telefónico celular 1 pertenece a | S1: Número Telefónico celular 2 | T1: Número Telefónico celular 2 a quien pertenece | U1: Número Telefónico celular 3 | V1: Número Telefónico Celular 3 a quien pertenece | W1: Institución que estudia su formación regular | X1: Año de Estudio en su formación Regular | Y1: ¿Existe alguna alergia/enfermedad/ condición del estudiante que la institución debe tener en cuenta durante clases? | Z1: Indique si su representado tiene alguna Necesidad Educativa no asociada a una discapacidad | AA1: Si respondió SI Indique cual es la necesidad educativa
A2: 1 | B2: anysther2010@gmail.com | C2: 1o | D2: C (vespertino) | E2: Ashqui Aldas | F2: Elian Jared | G2: 1 | I2: 1851463610 | J2: 43326 | K2: 6 | L2: Ashqui Aldas | M2: Segundo Elias | N2: 0999287487 | O2: Miñarica II | P2: 032412153 | Q2: 0998727178 | R2: Madre del estudiante | S2: 0998490758 | U2: 0999886954 | V2: Otro familiar | W2: Unidad Educativa Bolivar | X2: 3o EGB | Z2: NO
A3: 2 | B3: elyces9mariela@hotmail.com | C3: 1o | D3: A (matutino) | E3: Aguinda Cevallos | F3: Eliana Saraí | H3: 1 | I3: 1851467108 | J3: 43339 | K3: 6 | L3: Cevallos Torres | M3: Elisa Mariela | N3: 1718749078 | O3: Alberto Rosero y Destacamento Patuca | P3: 032510303 | Q3: 0984890107 | R3: Madre del estudiante | S3: 0999086266 | T3: otro familiar | U3: 0999899151 | V3: Otro familiar | W3: Unidad Educativa Pedro Fermín Cevallos | X3: 3o EGB | Z3: NO
A4: 3 | B4: thaliapoaquiza3@gmail.com | C4: 1o | D4: A (matutino) | E4: Azogue Poaquiza | F4: Bayoleth Samantha | H4: 1 | I4: 1851324424 | J4: 42797 | K4: 8 | L4: Poaquiza Córdova | M4: Thalia Elizabeth | N4: Edad | O4: Bernardino Echeverría | Q4: 0962792383 | R4: Madre del estudiante | S4: 0986772950 | T4: otro familiar | W4: Unidad Educativa Mario Cobo Barona | X4: 3o EGB | Z4: NO
A5: 4 | B5: jaz-akire05@hotmail.com | C5: 1o | D5: A (matutino) | E5: Chamorro Martinez | F5: Dominick David | G5: 1 | I5: 1851402352 | J5: 43086 | K5: 7 | L5: Martinez Lema | M5: Erika Jazmina | N5: 1804898086 | O5: Huachi San Francisco | Q5: 0984226357 | R5: Madre del estudiante | S5: +593 98 359 1409 | T5: Padre | U5: +593 98 764 0971 | V5: Otro familiar | W5: Unidad Educativa Francisco Flor | X5: 4o EGB | Z5: NO
A6: 5 | B6: angie.villacres.v@gmail.com | C6: 1o | D6: A (matutino) | E6: León Villacrés | F6: Emma Joy | G6: 1 | I6: 1851545085 | J6: 43648 | K6: 6 | L6: Villacres Vicuña | M6: Angélica Eulalia | N6: 1804200416 | O6: Patate. Av. Ambato y calle C. | Q6: 0997643140 | R6: Madre del estudiante | S6: 0998045276 | T6: Padre | U6: 0994477971 | V6: Otro familiar | W6: Home Life Academy | X6: 2o EGB | Z6: NO
A7: 6 | B7: lorenamarybel@outlook.com | C7: 1o | D7: A (matutino) | E7: Mongón Choez | F7: Darla Valentina | H7: 1 | I7: 1851357812 | J7: 42922 | K7: 8 | L7: Choez Coloma | M7: Lorena Maribel | N7: 1804882361 | O7: Techo Propio | P7: 032867328 | Q7: 0958795732 | R7: Madre del estudiante | S7: 0980902469 | T7: Padre | U7: 0987148975 | V7: Otro familiar | W7: Unidad Educativa Ambato | X7: 4o EGB | Z7: NO
A8: 7 | B8: itsbolivar.1520@gmail.com | C8: 1o | D8: A (matutino) | E8: Real Silva | F8: Celeste Aylin | H8: 1 | I8: 1851409209 | J8: 43113 | K8: 7 | L8: Real Real | M8: Fermin Orlando | N8: 1804471215 | O8: Parroquia atahualpa calles destancamiento tiwinza a media cuadra del Cementerio | P8: 2527017 | Q8: 0995576548 | R8: Padre del estudiante | S8: 0998518409 | T8: Madre | W8: Unidad Educativa Ambato | X8: 2o EGB | Z8: NO
A9: 8 | B9: aidapomaquero@gmail.com | C9: 1o | D9: A (matutino) | E9: Sagñay Pomaquero | F9: Elian Mathias | G9: 1 | I9: 1851420800 | J9: 43157 | K9: 7 | L9: Pomaquero Pinda | M9: Aida Jaqueline | N9: 1803338035 | O9: Barrio Luz de América | P9: 0987761771 | Q9: 997569662 | R9: Madre del estudiante | S9: 0987761771 | T9: Padre | U9: 0983708779 | V9: Otro familiar | W9: Bolívar | X9: 3o EGB | Z9: NO
G10: =SUM(G4:G9) -> 3 | H10: 4
A12: No | B12: Dirección de correo electrónico | C12: CURSO | D12: PARALELO | E12: Apellidos del Estudiante | F12: Nombres del Estudiante | G12: M | H12: F | I12: Número de Cédula del Estudiante | J12: Fecha de Nacimiento del estudiante | K12: Edad | L12: Apellidos del Representante del Estudiante | M12: Nombres del Representante del Estudiante | N12: Número de cédula del Representante | O12: Dirección | P12: Número telefónico convencional | Q12: Número telefónico celular 1 | R12: Número telefónico celular 1 pertenece a | S12: Número Telefónico celular 2 | T12: Número Telefónico celular 2 a quien pertenece | U12: Número Telefónico celular 3 | V12: Número Telefónico Celular 3 a quien pertenece | W12: Institución que estudia su formación regular | X12: Año de Estudio en su formación Regular | Y12: ¿Existe alguna alergia/enfermedad/ condición del estudiante que la institución debe tener en cuenta durante clases? | Z12: Indique si su representado tiene alguna Necesidad Educativa no asociada a una discapacidad | AA12: Si respondió SI Indique cual es la necesidad educativa
A13: 1 | B13: jonnyacostab@gmail.com | C13: 1o | D13: B (vespertino) | E13: Acosta Vaca | F13: Jonathan Gabriel | G13: 1 | I13: 1759061474 | J13: 43370 | K13: 7 | L13: Acosta Bombón | M13: Jonny Luis | N13: 1802320174 | O13: Av. Cervantes y Jorge Carrera | P13: 2588791 | Q13: 998390912 | R13: Padre del estudiante | S13: 992588855 | T13: Madre | W13: Unidad Educativa Glenn Doman | X13: 3o EGB | Z13: NO
A14: 2 | B14: briggitebravo3d@gmail.com | C14: 1o | D14: B (vespertino) | E14: Arcos Bravo | F14: Elian Alejandro | G14: 1 | I14: 1758455586 | J14: 43086 | K14: 7 | L14: Bravo Bravo | M14: Briggite | N14: 1206813212 | O14: Av Miraflores pasaje las Orquídeas | P14: 0983117180 | Q14: 0983117180 | R14: Madre del estudiante | S14: 0982346722 | T14: Padre | U14: 099-509-1590 | V14: Otro familiar | W14: Unidad Educativa Sagrada Familia | X14: 4o EGB | Y14: Alergia a los ácaros y frío | Z14: NO
A15: 3 | B15: revelomaria69@gmail.com | C15: 1o | D15: B (vespertino) | E15: Benavides Revelo | F15: Martina Eunice | H15: 1 | I15: 1758840845 | J15: 43272 | K15: 7 | L15: Revelo Muñoz | M15: Maria Jose | N15: 0401737069 | O15: Izamba conjunto san Juan 1casa 3 calles Pedro de Macorís y Manizales | P15: 2821291 | Q15: 0980903526 | R15: Madre del estudiante | S15: 0987636877 | T15: otro familiar | U15: 0999382369 | V15: Padre | W15: Unidad educativa "San Pio x" | X15: 3o EGB | Z15: NO
A16: 4 | B16: revelomaria69@gmail.com | C16: 1o | D16: B (vespertino) | E16: Benavides Revelo | F16: Maya Fiorella | H16: 1 | I16: 1758840837 | J16: 43272 | K16: 7 | L16: Revelo Muñoz | M16: María José | N16: 0401737069 | O16: Izamba, conjunto San Juan 1 casa 3, calles San Pedro de Macorís y Manizales | P16: 2821291 | Q16: 0980903526 | R16: Madre del estudiante | S16: 0987636877 | T16: otro familiar | U16: 0999382369 | V16: Padre | W16: Unidad educativa "San Pio X" | X16: 3o EGB | Z16: NO
A17: 5 | B17: danielespin87@gmail.comda | C17: 1o | D17: B (vespertino) | E17: Espín Mancheno | F17: Juliana Lucía | H17: 1 | I17: 1851547016 | J17: 43656 | K17: 6 | L17: Espín Salas | M17: Darwin Daniel | N17: 1804216495 | O17: Pachacutec y Quingalumba | P17: 032512916 | Q17: 0984717378 | R17: Padre del estudiante | S17: 0998854403 | T17: Madre | W17: Unidad Educativa Rodríguez Albornoz | X17: 2o EGB | Z17: NO
A18: 6 | B18: ab.agavilanes89@outlook.es | C18: 1o | D18: B (vespertino) | E18: Gavilanes Guaman | F18: Brianna Yamile | H18: 1 | I18: 0650810260 | J18: 43038 | K18: 7 | L18: Gavilanes Panimboza | M18: Angel Bladimir | N18: 1804710083 | O18: Cevallos | P18: 033074174 | Q18: 0984116294 | R18: Padre del estudiante | S18: 0967476414 | T18: Madre | W18: Unidad Educativa Alberto Guerra | X18: 3o EGB | Y18: No | Z18: NO
A19: 7 | B19: rafa832@hotmail.com | C19: 1o | D19: B (vespertino) | E19: Jara Casillas | F19: Arianne Belén | H19: 1 | I19: 1851476083 | J19: 43372 | K19: 7 | L19: Jara Espin | M19: Julio Rafael | N19: 1803340163 | O19: Av. Luis Anibal Granja y Libardo Parra | P19: 035016915 | Q19: 0984274104 | R19: Madre del estudiante | S19: 0992872558 | T19: Padre | U19: 0992541184 | V19: Otro familiar | W19: Unidad Educativa Espiritu Santo | X19: 3o EGB | Y19: La mencionada estudiante es vegetariana al 100% | Z19: NO
A20: 8 | B20: mc.intriago7@gmail.com | C20: 1o | D20: B (vespertino) | E20: Lema Intriago | F20: Celeste Valentina | H20: 1 | I20: 1851375772 | J20: 42990 | K20: 7 | L20: Intriago Pilamunga | M20: María del Carmen | N20: 1804381273 | O20: Imbabura y Esparza | P20: 032849242 | Q20: 0984038188 | R20: Madre del estudiante | S20: 0987630585 | T20: Padre | U20: 0984038188 | V20: Madre | W20: Unidad Educativa Emanuel | X20: 4o EGB | Y20: No | Z20: NO
A21: 9 | B21: pazmino.rebeca_87@yahoo.com | C21: 1o | D21: B (vespertino) | E21: López Pazmiño | F21: Elí Natanael | G21: 1 | I21: 1851416501 | J21: 43141 | K21: 7 | L21: Pazmiño Vargas | M21: Rebeca Jeannette | N21: 1804316493 | O21: San Vicente | Q21: 0999268085 | R21: Madre del estudiante | S21: 0984554748 | T21: Padre | U21: 098-732-0081 | V21: Otro familiar | W21: San Isidro Labrador | X21: 3o EGB | Z21: SI | AA21: Un ojo no puede ver
A22: 10 | B22: ambamielecuador@gmail.com | C22: 1o | D22: B (vespertino) | E22: Mantilla Paredes | F22: Elisa Margoth | H22: 1 | I22: 1851394054 | J22: 43055 | K22: 7 | L22: Paredes Rodríguez | M22: Fernanda Elizabeth | N22: 1804621454 | O22: Av. Jacome Clavijo e Isaías Toro Ruiz | Q22: 0984768823 | R22: Madre del estudiante | S22: 0939147271 | T22: Padre | W22: Unidad Educativa Novus High School | X22: 3o EGB | Y22: No | Z22: NO
A23: 11 | B23: ramospiedad540@gmail.com | C23: 1o | D23: B (vespertino) | E23: Manzano Ramos | F23: Noemí Hadassah | H23: 1 | I23: 1851366599 | J23: 42955 | K23: 7 | L23: Manzano Tonato | M23: Henry Nelson | N23: 1803296019 | O23: Mocha- Caserío Acapulco | Q23: 0981843865 | R23: Padre del estudiante | S23: 0995984826 | T23: Madre | W23: UNIDAD EDUCATIVA EMANUEL | X23: 3o EGB | Z23: NO
A24: 12 | B24: myligol501@gmail.com | C24: 1o | D24: B (vespertino) | E24: Masabanda Contreras | F24: Janis Emilia | H24: 1 | I24: 1851443570 | J24: 43246 | K24: 7 | L24: Contreras Alqui | M24: Mayra Olivia | N24: 1804263257 | O24: Av. Victor Hugo y Batalla de Pichincha | P24: 0997730918 | Q24: 099 741 9565 | R24: Padre del estudiante | S24: 0997730918 | T24: Madre | U24: 0984309883 | V24: Padre | W24: Unidad educativa Rodríguez Albornoz | X24: 3o EGB | Z24: NO
A25: 13 | B25: majrock1@yahoo.es | C25: 1o | D25: B (vespertino) | E25: Ñacato Ulloa | F25: Danna Rafaela | H25: 1 | I25: 1759221938 | J25: 43439 | K25: 6 | L25: Ñacato Anchaluisa | M25: Byron Rafael | N25: 1803012374 | O25: Alexander Fleming y Galileo Galilei Conjunto habitacional Portón del Bosque casa 4 | P25: 0994975161 | Q25: 0994975161 | R25: Padre del estudiante | S25: 0997374843 | T25: Madre | W25: UNIDAD EDUCATIVA EUGENIO ESPEJO | X25: 3o EGB | Z25: NO
A26: 14 | B26: eaparedes2@gmail.com | C26: 1o | D26: B (vespertino) | E26: Paredes Armas | F26: David Eduardo | G26: 1 | I26: 1851487890 | J26: 43415 | K26: 6 | L26: Paredes Paredes | M26: Eduardo Antonio | N26: 1803159712 | O26: Calle Mera y Cuenca | P26: 032841386 | Q26: 0987289260 | R26: Padre del estudiante | S26: 0999140506 | T26: Madre | W26: Unidad Educativa Santo Domingo de Guzmán Ambato | X26: 3o EGB | Z26: NO
A27: 15 | B27: byper34@hotmail.com | C27: 1o | D27: B (vespertino) | E27: Pérez Llanos | F27: Valery MIkaela | H27: 1 | I27: 1851429710 | J27: 43191 | K27: 7 | L27: Llanos Bonilla | M27: Piedad Maricely | N27: 1803086213 | O27: Martinez | Q27: 0998806683 | R27: Madre del estudiante | S27: 0999915604 | T27: Padre | U27: 0980111663 | V27: Otro familiar | W27: Unidad Educativa Ambato | X27: 3o EGB | Z27: NO
A28: 16 | B28: ma-fer92@hotmail.com | C28: 1o | D28: B (vespertino) | E28: Pérez Romo | F28: Martin Israel | G28: 1 | I28: 1851524577 | J28: 43563 | K28: 7 | L28: Romo Muñoz | M28: María Fernanda | N28: 1804664488 | O28: Av. 22 de enero cueva de los tayos | Q28: 0983715062 | R28: Madre del estudiante | S28: 0984447397 | T28: Padre | W28: Nueva Esperanza | X28: 2o EGB | Y28: Sinusitis | Z28: NO
A29: 17 | B29: paulsanchez25@gmail.com | C29: 1o | D29: B (vespertino) | E29: Sánchez Maldonado | F29: Axel Rafael | G29: 1 | I29: 1851393296 | J29: 43054 | K29: 7 | L29: Sánchez Acosta | M29: Paúl Sebastián | N29: 1803540101 | O29: Serafín Pulgar y Cesar Guerrero | Q29: 0961477901 | R29: Padre del estudiante | S29: 0984759551 | T29: Madre | W29: Unidad Educativa General Córdova | X29: 4o EGB | Z29: NO
A30: 18 | B30: Isavillenacardenas@gmail.com | C30: 1o | D30: B (vespertino) | E30: Sánchez Villena | F30: José Julián | G30: 1 | I30: 1851502391 | J30: 43475 | K30: 6 | L30: Villena Cárdenas | M30: María Isabel | N30: 1803096419 | O30: Jácome Clavijo y Marcos Montalvo | P30: 032842175 | Q30: 0987738663 | R30: Madre del estudiante | S30: 0984865981 | T30: otro familiar | U30: 0959708241 | V30: Otro familiar | W30: Pio X | X30: 2o EGB | Y30: Rinitis alergica | Z30: NO
A31: 19 | B31: adrianaborjacalderon@gmail.com | C31: 1o | D31: B (vespertino) | E31: Solórzano Borja | F31: Benjamín Caleb | G31: 1 | I31: 1851405561 | J31: 43099 | K31: 7 | L31: Borja Calderón | M31: Adriana Elizabeth | N31: 1803144995 | O31: Av Pichincha y Latacunga | Q31: 0992836153 | R31: Madre del estudiante | S31: +593 99 994 9104 | T31: otro familiar | U31: +593 99 877 9828 | V31: Madre | W31: Unidad Educativa Jerusalén | X31: 2o EGB | Z31: NO
A32: 20 | B32: musicaluis11@gmail.com | C32: 1o | D32: B (vespertino) | E32: Sumbana Freire | F32: Isaac Daniel | G32: 1 | I32: 1851513034 | J32: 43517 | K32: 6 | L32: Sumbana Quinapanta | M32: Luis Enrique | N32: 1802884542 | O32: Avenida Los Chasquiz y Río Yanayacu E24 ciudadela Nuevo Ambato | P32: 032846142 | Q32: 0998065024 | R32: Padre del estudiante | S32: 0979105161 | T32: Madre | U32: 0995583840 | V32: Otro familiar | W32: U.E. Juan León Mera ,"La Salle" | X32: 2o EGB | Y32: Ninguna | Z32: NO
A33: 21 | B33: adry1087@gmail.com | C33: 1o | D33: B (vespertino) | E33: Zamora Chafla | F33: Ian Esteban | G33: 1 | I33: 1851444370 | J33: 43249 | K33: 7 | L33: Chafla Bonilla | M33: Adriana Fernanda | N33: 1804087805 | O33: Ernesto Miño y Manuel Garcés | Q33: 0987320777 | R33: Madre del estudiante | S33: 0984212679 | T33: otro familiar | W33: Unidad Educativa Eloy Alfaro | X33: 2o EGB
G34: 10 | H34: 11
A37: No | B37: Dirección de correo electrónico | C37: CURSO | D37: PARALELO | E37: Apellidos del Estudiante | F37: Nombres del Estudiante | G37: M | H37: F | I37: Número de Cédula del Estudiante | J37: Fecha de Nacimiento del estudiante | K37: Edad | L37: Apellidos del Representante del Estudiante | M37: Nombres del Representante del Estudiante | N37: Número de cédula del Representante | O37: Dirección | P37: Número telefónico convencional | Q37: Número telefónico celular 1 | R37: Número telefónico celular 1 pertenece a | S37: Número Telefónico celular 2 | T37: Número Telefónico celular 2 a quien pertenece | U37: Número Telefónico celular 3 | V37: Número Telefónico Celular 3 a quien pertenece | W37: Institución que estudia su formación regular | X37: Año de Estudio en su formación Regular | Y37: ¿Existe alguna alergia/enfermedad/ condición del estudiante que la institución debe tener en cuenta durante clases? | Z37: Indique si su representado tiene alguna Necesidad Educativa no asociada a una discapacidad | AA37: Si respondió SI Indique cual es la necesidad educativa
A38: 1 | B38: alexcaguana93@gmail.com | C38: 1o | D38: C (vespertino) | E38: Caguana Paucar | F38: Leonel Emiliano | G38: 1 | I38: 1851375061 | J38: 42987 | K38: 7 | L38: Caguana Chasig | M38: Alex Humberto | N38: 1804835153 | O38: Quisapincha, Ecuador | Q38: 0982667532 | R38: Padre del estudiante | S38: 0984576355 | T38: Madre | U38: 0994484370 | V38: Otro familiar | W38: Unidad Educativa Rumiñahui | X38: 4o EGB | Y38: Ningúna | Z38: NO
A39: 2 | B39: gabogus1804@hotmail.com | C39: 1o | D39: C (vespertino) | E39: Chisag Mayorga | F39: Paulette Milagros | H39: 1 | I39: 1851467132 | J39: 43339 | K39: 6 | L39: Chisag Pallmay | M39: Wellington Gustavo | N39: 1804332292 | O39: Avenida Víctor Hugo y calle José de la cuadra | P39: 0961308439 | Q39: 0995123748 | R39: Padre del estudiante | S39: 0961308439 | T39: Madre | U39: 0960422007 | V39: Otro familiar | W39: Unidad Educativa Rodriguez Albornoz | X39: 3o EGB | Y39: Tiene alergia a todo tipo de insectos | Z39: NO
A40: 3 | B40: mary.trabajo44@gmail.com | C40: 1o | D40: C (vespertino) | E40: Culque Rumipamba | F40: María Alejandra | H40: 1 | I40: 1758171878 | J40: 42916 | K40: 8 | L40: Rumipamba López | M40: Dora Maricela | N40: 1803386489 | O40: Av José Peralta y Hugo Alemán | Q40: 0992933915 | R40: Madre del estudiante | S40: 0999297092 | T40: Padre | U40: 0992641911 | V40: Otro familiar | W40: Unidad Educativa Santo Domingo de Guzman | X40: 4o EGB | Y40: Alergia al polvo y frío | Z40: NO
A41: 4 | B41: guachambaladanny1@gmail.com | C41: 1o | D41: C (vespertino) | E41: Cunama Guachambala | F41: Reilly Henry | G41: 1 | I41: 1851502821 | J41: 43477 | K41: 6 | L41: Guachambala Masaquiza | M41: Diana Maribel | N41: 1804132726 | O41: Huambalo_ La florida | Q41: 0979469831 | R41: Madre del estudiante | S41: 0995302495 | T41: otro familiar | U41: 0986334644 | V41: Padre | W41: Escuela de educación básica Marianita de Jesús | X41: 2o EGB | Y41: Ninguna | Z41: NO
A42: 5 | B42: curicamarocio@gmail.com | C42: 1o | D42: C (vespertino) | E42: Curicama Curicama | F42: Camila Valentina | H42: 1 | I42: 1851418523 | J42: 43147 | K42: 7 | L42: Curicama Gualli | M42: Rosio | N42: 1803388832 | O42: Av Luis Aníbal Granja y Carlos Cando | P42: 2826672 | Q42: 962581735 | R42: Madre del estudiante | S42: 979113539 | T42: Padre | U42: 987744347 | V42: Otro familiar | W42: Unidad Educativa Emanuel | X42: 4o EGB | Z42: NO
A43: 6 | B43: vivilmgualpa1601@gmail.com | C43: 1o | D43: C (vespertino) | E43: Freire Gualpa | F43: Esteban Emilio | G43: 1 | I43: 1851433456 | J43: 43203 | K43: 7 | L43: Gualpa Almache | M43: Katherine Viviana | N43: 1804569547 | O43: Terremoto, av. Bolivariana y Efraín Guevara Conjunro residencial Alcalá #17 | P43: 032415895 | Q43: 0992572150 | R43: Madre del estudiante | S43: 0995310924 | T43: Padre | U43: 0987769074 | V43: Otro familiar | W43: Unidad Educativa Andino | X43: 2o EGB | Z43: NO
...

Sheet 2o
A1: No | B1: Dirección de correo electrónico | C1: CURSO | D1: PARALELO | E1: Apellidos del Estudiante | F1: Nombres del Estudiante | G1: M | H1: F | I1: Instrumento que estudia en el Conservatorio Bolívar | J1: Maestro de Instrumento | K1: Número de Cédula del Estudiante | L1: Fecha de Nacimiento del estudiante | M1: Edad | N1: Apellidos del Representante del Estudiante | O1: Nombres del Representante del Estudiante | P1: Número de cédula del Representante | Q1: Dirección | R1: Número telefónico convencional | S1: Número telefónico celular 1 | T1: Número telefónico celular 1 pertenece a | U1: Número Telefónico celular 2 | V1: Número Telefónico celular 2 a quien pertenece | W1: Número Telefónico celular 3 | X1: Número Telefónico Celular 3 a quien pertenece | Y1: Institución que estudia su formación regular | Z1: Año de Estudio en su formación Regular | AA1: ¿Existe alguna alergia/enfermedad/ condición del estudiante que la institución debe tener en cuenta durante clases? | AB1: Indique si su representado tiene alguna Necesidad Educativa no asociada a una discapacidad | AC1: Si respondió SI Indique cual es la necesidad educativa
A2: 1 | B2: ivan-ap01@hotmail.com | C2: 2o | D2: A (matutina) | E2: Acosta Ruíz | F2: Samuel Alexander | G2: 1 | I2: saxofon | J2: Toapanta Arequipa Danny Alexander | K2: 1851304558 | L2: 42724 | M2: 8 | N2: Acosta Peña | O2: Rodolfo Iván | P2: 1803296290 | Q2: Julio Cesar cañar y Silva Pareja | R2: 032405777 | S2: 0995850407 | T2: Padre del estudiante | U2: 0993639387 | V2: otro familiar | W2: 0994831682 | X2: Otro familiar | Y2: Unidad Educativa Ambato | Z2: 5o EGB | AB2: NO
A3: 2 | B3: djivan199314@gmail.com | C3: 2o | D3: A (matutina) | E3: Caiza Hurtado | F3: Joseph Emiliano | G3: 1 | I3: guitarra | J3: Chicaiza Cuenca Rubén Geovany | K3: 1851304731 | L3: 42353 | M3: 8 | N3: Caiza Jaque | O3: Henry Ivan | P3: 1804906566 | Q3: Izamba Quillan Loma | S3: 0992758070 | T3: Padre del estudiante | U3: 0986494911 | V3: Madre | W3: 0995130589 | X3: Otro familiar | Y3: Unidad Educativa Atahualpa | Z3: 5o EGB | AA3: No | AB3: NO
A4: 3 | B4: diana.deby.basantes85@gmail.com | C4: 2o | D4: A (matutina) | E4: Cárdenas Basantes | F4: Samara Elizabeth | H4: 1 | I4: piano | J4: Chicaiza Yánez Jefferson Alexander | K4: 1851391316 | L4: 43047 | M4: 7 | N4: Basantes Yugcha | O4: Diana Elizabeth | P4: 0503699654 | Q4: García Moreno Y Vargas Torres ( Frente al colegio Ambato al fondo de un zaguan junto una vulcanizadora casa color mostaza con vivo ) | S4: 0984629080 | T4: Madre del estudiante | U4: 0999901815 | V4: Padre | Y4: Unidad Educativa '' Ambato'' | Z4: 4o EGB
A5: 4 | B5: veronicatoasa@gmail.com | C5: 2o | D5: A (matutina) | E5: Chaglla Toasa | F5: Ayeleth Hadasha | H5: 1 | I5: piano | J5: Chicaiza Yánez Jefferson Alexander | K5: 1851278679 | L5: 42628 | M5: 8 | N5: Toasa Vega | O5: Verónica Elizabeth | P5: 1804826681 | Q5: Azorrin y Jacinto Verdaguer | R5: 032400895 | S5: 0995165267 | T5: Madre del estudiante | U5: 0995818097 | V5: Padre | W5: 0983724953 | X5: Otro familiar | Y5: Unidad Educativa Bolivar | Z5: 5o EGB | AB5: NO
A6: 5 | B6: valeriagaltamirano@gmail.com | C6: 2o | D6: A (matutina) | E6: Chisag Guamán | F6: Ricardo Sebastián | G6: 1 | I6: trompeta | J6: Amancha Hidalgo Félix Marcelo | K6: 1851367969 | L6: 42961 | M6: 7 | N6: Chisag Pallmay | O6: Edwin Ricardo | P6: 1804609418 | Q6: Av. Víctor Hugo y José de la Cuadra | R6: 2512107 | S6: 0983459828 | T6: Madre del estudiante | U6: 0984793634 | V6: Padre | W6: 0969000799 | X6: Otro familiar | Y6: U.E.Francisco Flor | Z6: 4o EGB
A7: 6 | B7: tanniabimboza@gmail.com | C7: 2o | D7: A (matutina) | E7: Chulco Bimboza | F7: Dereck David | H7: 1 | I7: guitarra | J7: Chicaiza Cuenca Rubén Geovany | K7: 1851245272 | L7: 42501 | M7: 9 | N7: Bimboza Castro | O7: Tannia Mariela | P7: 1805139738 | Q7: Huachi la Florida | S7: 0995318655 | T7: Madre del estudiante | U7: 0995586336 | V7: Padre | W7: 0995318655 | X7: Madre | Y7: UE Bolivar | Z7: 5o EGB | AB7: NO
A8: 7 | B8: valenciaanny12@gmail.com | C8: 2o | D8: A (matutina) | E8: Guerrero Valencia | F8: Dylan Nicolás | H8: 1 | I8: piano | J8: Chicaiza Orozco Marcelo Javier | K8: 1851351658 | L8: 42898 | M8: 8 | N8: Valencia Lema | O8: Ana Beatriz | P8: 1805382593 | Q8: Santa Rosa | S8: 958909852 | T8: Madre del estudiante | U8: 987729007 | V8: Padre | W8: 0984052423 | X8: Otro familiar | Y8: Unidad Educativa Ambato | Z8: 4o EGB | AB8: NO
A9: 8 | B9: carlarivadeneira@yahoo.es | C9: 2o | D9: A (matutina) | E9: Jiménez Rivadeneira | F9: Amelia Sofía | G9: 1 | I9: violín | J9: Gutama Galan Juan Diego | K9: 1851385904 | L9: 43018 | M9: 7 | N9: Rivadeneira Mejía | O9: Carla Maritza | P9: 1719780304 | Q9: Calle Morales y Batalla de Tarqui, S/N, cerramiento celeste, casa de un piso junto a la Unidad Educativa "Guayaquil", diagonal a la puerta del estadio de la Unidad. | R9: 032525543 | S9: 0994639747 | T9: Madre del estudiante | U9: 0983819961 | V9: Padre | W9: 0987477681 | X9: Otro familiar | Y9: Unidad Educativa "Guayaquil" | Z9: 3o EGB | AB9: NO
A10: 9 | B10: sandrapio1979@gmail.com | C10: 2o | D10: A (matutina) | E10: López Iza | F10: Eduardo José | G10: 1 | I10: trombón | J10: Peralta Aponte Christian Hernán | K10: 1851319101 | L10: 42779 | M10: 8 | N10: López Núñez | O10: Carlos Eduardo | P10: 1803009461 | Q10: Pinllo | S10: 0990360880 | T10: Padre del estudiante | U10: 0984057751 | V10: Madre | W10: 0997895624 | X10: Otro familiar | Y10: Escuela Juan Montalvo | Z10: 4o EGB | AB10: NO
A11: 10 | B11: katro7ch@gmail.com | C11: 2o | D11: A (matutina) | E11: Martinez Chafla | F11: Zoe Ivanna | H11: 1 | I11: violín | J11: Gutama Galan Juan Diego | K11: 1758349755 | L11: 43021 | M11: 7 | N11: Chafla Fierro | O11: Katya del Rocio | P11: 1714688064 | Q11: Ambato Calle Montalvo 222 y Cuenca | R11: 2426313 | S11: 0980609987 | T11: Madre del estudiante | U11: 0999944642 | V11: Padre | W11: 0999738219 | X11: Otro familiar | Y11: ACE /JOSUE | Z11: 3o EGB
A12: 11 | B12: anitamedina8019@gmail.com | C12: 2o | D12: A (matutina) | E12: Muñiz Medina | F12: Israel Roberto | G12: 1 | I12: percusión | J12: Tapia García Kevin Paúl | K12: 1851351898 | L12: 42899 | M12: 8 | N12: Medina Santa Cruz | O12: Mayra Anabel | P12: 183090230 | Q12: Santa Rosa | S12: 0991235833 | T12: Madre del estudiante | U12: 0997809263 | V12: Padre | Y12: Pedro Fermín Cevallos | Z12: 4o EGB | AA12: No | AB12: NO
A13: 12 | B13: gabytatoasa.94@gmail.com | C13: 2o | D13: A (matutina) | E13: Muñoz Toasa | F13: Karla Sarahí | H13: 1 | I13: violín | J13: Gutama Galan Juan Diego | K13: 0650721038 | L13: 42640 | M13: 8 | N13: Toasa Toasa | O13: Gabriela Aracely | P13: 1600786758 | Q13: Santa rosa | S13: 0992656814 | T13: Madre del estudiante | U13: 0991567097 | V13: otro familiar | W13: 0999214775 | X13: Padre | Y13: Gral Eloy Alfaro delgado | Z13: 5o EGB | AB13: NO
A14: 13 | B14: marisoltoasa.mt@gmail.com | C14: 2o | D14: A (matutina) | E14: Quispe Toasa | F14: Arlet Sarahi | H14: 1 | I14: violonchelo | J14: Peña Núñez Andrea Michelle | K14: 1851339125 | L14: 42828 | M14: 8 | N14: Toasa Aldas | O14: Marisol Alejandra | P14: 1803582152 | Q14: Pinllo barrio Andiglata | R14: 0000000 | S14: 0998786172 | T14: Madre del estudiante | U14: 0999571966 | V14: Padre | W14: 0986208010 | X14: Otro familiar | Y14: Unidad Educativa Bolivar | Z14: 3o EGB | AB14: NO
A15: 14 | B15: roli.ramos@hotmail.com | C15: 2o | D15: A (matutina) | E15: Ramos Chango | F15: Mathias Jair | G15: 1 | I15: piano | J15: Pérez Toapanta Diego Armando | K15: 1851345155 | L15: 39219 | M15: 8 | N15: Ramos Miniguano | O15: Franklin Ramos | P15: 1802893949 | Q15: La Nación y El Fenix | R15: 0983309144 | S15: 0983309144 | T15: Padre del estudiante | U15: 0979324698 | V15: Madre | W15: 0968966464 | X15: Otro familiar | Y15: Conservatorio ambato | Z15: 2o EGB | AB15: NO
A16: 15 | B16: arquirecord@gmail.com | C16: 2o | D16: A (matutina) | E16: Revelo Pico | F16: Alessandro Salvatore | G16: 1 | I16: trompeta | J16: Amancha Hidalgo Félix Marcelo | K16: 0961388386 | L16: 42797 | M16: 8 | N16: Revelo Córdova | O16: Jorge Luis | P16: 1802689610 | Q16: Av de los Shyris y Diego Noboa | R16: 00 | S16: 0983805776 | T16: Padre del estudiante | U16: 0982362628 | V16: Madre | W16: 0960966023 | X16: Otro familiar | Y16: Unidad Educativa Bolívar | Z16: 4o EGB | AA16: Alergia al polvo | AB16: NO
A17: 16 | B17: cynthiaruizcastillo1@gmail.com | C17: 2o | D17: A (matutina) | E17: Solis Ruiz | F17: Lenin Gabriel | G17: 1 | I17: guitarra | J17: Chicaiza Cuenca Rubén Geovany | K17: 1851291904 | L17: 42674 | M17: 8 | N17: Ruiz Castillo Cynthia Lizbeth | O17: Ruiz Castillo Cynthia Lizbeth | P17: 1804937793 | Q17: Samanga, Camino el Rey y Calle Palora | S17: 0983787366 | T17: Madre del estudiante | U17: 0997088600 | V17: otro familiar | W17: 0984231715 | X17: Otro familiar | Y17: Unidad Educativa Juan Montalvo | Z17: 5o EGB | AA17: Si | AB17: NO
A18: 17 | B18: mikaelaavalos20@gmail.com | C18: 2o | D18: A (matutina) | E18: Toapanta Avalos | F18: Ariana Nicole | H18: 1 | I18: trompeta | J18: Amancha Hidalgo Félix Marcelo | K18: 1851362275 | L18: 42939 | M18: 7 | N18: Avalos Tixelema | O18: Silvia Micaela | P18: 1804367595 | Q18: La Península sector Catiglata | R18: 032445623 | S18: 0982700302 | T18: Madre del estudiante | U18: 0993321424 | V18: Padre | Y18: Unidad Educativa Bolivar | Z18: 4o EGB | AB18: NO
G19: =SUM(G2:G18) -> 9 | H19: =SUM(H2:H18) -> 8
A21: No | B21: Dirección de correo electrónico | C21: CURSO | D21: PARALELO | E21: Apellidos del Estudiante | F21: Nombres del Estudiante | G21: M | H21: F | I21: Instrumento que estudia en el Conservatorio Bolívar | J21: Maestro de Instrumento | K21: Número de Cédula del Estudiante | L21: Fecha de Nacimiento del estudiante | M21: Edad | N21: Apellidos del Representante del Estudiante | O21: Nombres del Representante del Estudiante | P21: Número de cédula del Representante | Q21: Dirección | R21: Número telefónico convencional | S21: Número telefónico celular 1 | T21: Número telefónico celular 1 pertenece a | U21: Número Telefónico celular 2 | V21: Número Telefónico celular 2 a quien pertenece | W21: Número Telefónico celular 3 | X21: Número Telefónico Celular 3 a quien pertenece | Y21: Institución que estudia su formación regular | Z21: Año de Estudio en su formación Regular | AA21: ¿Existe alguna alergia/enfermedad/ condición del estudiante que la institución debe tener en cuenta durante clases? | AB21: Indique si su representado tiene alguna Necesidad Educativa no asociada a una discapacidad | AC21: Si respondió SI Indique cual es la necesidad educativa
A22: 1 | B22: chave287@hotmail.com | C22: 2o | D22: B (vespertina) | E22: Alvarado Chávez | F22: Mathias Josue | G22: 1 | I22: guitarra | J22: Chicaiza Cuenca Rubén Geovany | K22: 1851386316 | L22: 43004 | M22: 7 | N22: Chávez Rugel | O22: Maria Gabriela | P22: 1803521424 | Q22: Cesar Silva y Sergio Nuñez | S22: 0998004437 | T22: Madre del estudiante | U22: 0988186974 | V22: Padre | Y22: Unidad educativa Bautista | Z22: 4o EGB | AA22: No | AB22: NO
A23: 2 | B23: mariazoilayuquilema9554@gmail.com | C23: 2o | D23: B (vespertina) | E23: Anilema Yuquilema | F23: Aylen Yuleisy | H23: 1 | I23: violín | J23: Zumbana Quinapanta Santiago Maximiliano | K23: 0550902993 | L23: 42707 | M23: 8 | N23: Yuquilema Lema | O23: María Zoila | P23: 0504289554 | Q23: Km8 vía Baños | S23: 0984499689 | T23: Madre del estudiante | U23: 0999388791 | V23: Padre | W23: 0986144323 | X23: Otro familiar | Y23: Sergio Quirola | Z23: 5o EGB | AB23: NO
A24: 3 | B24: crisfernuez@gmail.com | C24: 2o | D24: B (vespertina) | E24: Campaña Núñez | F24: Lucia Guadalupe | H24: 1 | I24: violín | J24: Zumbana Quinapanta Santiago Maximiliano | K24: 1851311744 | L24: 42752 | M24: 8 | N24: Núñez Núñez | O24: Cristina Fernanda | P24: 1804611091 | Q24: Av.Julio Cesar Cañar y Pedro Hecheveria | R24: +59335017806 | S24: 0998832667 | T24: Madre del estudiante | U24: 0979125026 | V24: Padre | W24: 0979120030 | X24: Otro familiar | Y24: Unidad Educativa Bolivar | Z24: 4o EGB | AB24: NO
A25: 4 | B25: wilmagarces2014@gmail.com | C25: 2o | D25: B (vespertina) | E25: Chávez Garcés | F25: Ángel David | G25: 1 | I25: violín | J25: Zumbana Quinapanta Santiago Maximiliano | K25: 1851315190 | L25: 42765 | M25: 8 | N25: Garcés Herrera | O25: Wilma Mercedes | P25: 1802778454 | Q25: Calle Cartago y av. Indoamérica | S25: 0985113100 | T25: Madre del estudiante | U25: 0984668312 | V25: Padre | W25: 0999781215 | X25: Otro familiar | Y25: Unidad Educativa España | Z25: 4o EGB | AB25: NO
A26: 5 | B26: fer_srobles@hotmail.com | C26: 2o | D26: B (vespertina) | E26: Cruz Sotomayor | F26: Cayetano Javier | G26: 1 | I26: percusión | J26: Tapia García Kevin Paúl | K26: 1851386621 | L26: 43001 | M26: 7 | N26: Sotomayor Robles | O26: María Fernanda | P26: 1804144432 | Q26: Av. Albert Einstein y Jonás Salk conjunto Venecia, casa 6 externo | S26: 0984456234 | T26: Madre del estudiante | U26: 0984593351 | V26: otro familiar | W26: 0998164126 | X26: Otro familiar | Y26: Institución educativa La Merced | Z26: 3o EGB | AA26: Alergia a los bichos, mosquitos | AB26: NO
A27: 6 | B27: marthatipanluiza@gmail.com | C27: 2o | D27: B (vespertina) | E27: Gaibor Tipanluiza | F27: Nahomy Isabella | H27: 1 | I27: contrabajo | J27: Vasquez Sánchez David Hernán | K27: 1851304624 | L27: 42691 | M27: 8 | N27: Tipanluiza Ramírez | O27: Martha Susana | P27: 1802946457 | Q27: Conjunto Tulipanes la Península | R27: 2445083 | S27: 0983714129 | T27: Madre del estudiante | U27: 0983194425 | V27: Padre | W27: 0989857317 | X27: Otro familiar | Y27: UE Nueva Esperanza | Z27: 5o EGB | AB27: NO
A28: 7 | B28: mfm380146@gmail.com | C28: 2o | D28: B (vespertina) | E28: Guamán Flores | F28: Mathías Leonel | G28: 1 | I28: saxofon | J28: Arevalo Catañeda Angel Jorge | K28: 1758455750 | L28: 43087 | M28: 7 | N28: Flores Montenegro | O28: Mayra Adela | P28: 2100426853 | Q28: Av. Luís Pasteur y Surinam | S28: 0995597637 | T28: Madre del estudiante | U28: 0987070059 | V28: Padre | Y28: U. E. La Merced | Z28: 4o EGB
A29: 8 | B29: martinez2004karen@gmail.com | C29: 2o | D29: B (vespertina) | E29: Herrera Martínez | F29: María Alejandra | H29: 1 | I29: piano | J29: Quinapanta Tibán Angel Rodrigo | K29: 1851399889 | L29: 43076 | M29: 7 | N29: Martinez Valdiviezo | O29: Karina Alexandra | P29: 1805089669 | Q29: Antonio Ante y Febres Cordero | R29: 032445924 | S29: 0979262975 | T29: Madre del estudiante | U29: 0995832776 | V29: Padre | W29: 0984864949 | X29: Padre | Y29: Unidad educativa Manuela Espejo | Z29: 4o EGB | AB29: NO
A30: 9 | B30: anaguaman2024@gmail.com | C30: 2o | D30: B (vespertina) | E30: Maisanche Guaman | F30: Maykel Leonel | G30: 1 | I30: clarinete | J30: Guananga Aizabucha Javier Santiago | K30: 0550933204 | L30: 42844 | M30: 8 | N30: Guaman Chimbana | O30: Ana Lucia | P30: 1850311190 | Q30: Parroquia Constantino Fernandez Barrio San vicente | S30: 0994530363 | T30: Madre del estudiante | U30: 0959754546 | V30: Padre | W30: 0986708583 | X30: Otro familiar | Y30: Unidad Educativa Honorato Vasquez | Z30: 3o EGB | AB30: NO
A31: 10 | B31: anamarisolsalinasfreire@gmail.com | C31: 2o | D31: B (vespertina) | E31: Marfetán Salinas | F31: Andrea Belén | H31: 1 | I31: piano | J31: Díaz Loyola David Descartes | K31: 1851383586 | L31: 43018 | M31: 7 | N31: Salinas Freire | O31: Ana Marisol | P31: 1803017241 | Q31: Huachi Grande, Barrio Gran Colombia. Av. Atahualpa y hawai | R31: 00000000 | S31: 0994602389 | T31: Madre del estudiante | U31: 0999463698 | V31: Padre | W31: 0968351721 | X31: Otro familiar | Y31: Unidad Educativa Eugenio Espejo | Z31: 4o EGB | AB31: NO
A32: 11 | B32: gabbylo3ruby@gmail.com | C32: 2o | D32: B (vespertina) | E32: Martínez López | F32: Wendy Sofía | H32: 1 | I32: piano | J32: Caiza Caiza Roberto Carlos | K32: 1851277531 | L32: 42611 | M32: 8 | N32: López Guaño | O32: Gabriela López | P32: 1804636692 | Q32: Ingahurco | R32: 032452490 | S32: 0984001866 | T32: Madre del estudiante | U32: 0984306986 | V32: Padre | W32: 032452490 | X32: Otro familiar | Y32: Unidad Educativa " Bolívar" | Z32: 5o EGB | AB32: NO
A33: 12 | B33: patricia.d.espinoza.s@gmail.com | C33: 2o | D33: B (vespertina) | E33: Muzo Espinoza | F33: Paúl Alejandro | G33: 1 | I33: trompeta | J33: Pérez Mayorga Edwin Israel | K33: 1851390607 | L33: 43042 | M33: 8 | N33: Espinoza Silva | O33: Diane Patricia | P33: 1716547565 | Q33: Cervantes y Ernesto Alvarado | R33: 0984598996 | S33: 0984598996 | T33: Madre del estudiante | U33: 0995887999 | V33: Padre | W33: 0986008973 | X33: Otro familiar | Y33: Lasalle | Z33: 4o EGB | AA33: Rinitis alergica | AB33: NO
A34: 13 | B34: charlobelldyn@gmail.com | C34: 2o | D34: B (vespertina) | E34: Nuñez Conteron | F34: Yanniz Charlotte | H34: 1 | I34: piano | J34: Acosta Zagal Karolina | K34: 1851308013 | L34: 42738 | M34: 8 | N34: Conteron Jalca | O34: Ana Isabel | P34: 1803332673 | Q34: Av.Quiz Quiz y Cañaris Ciudadela San Antonio | R34: 032412115 | S34: 0998609682 | T34: Madre del estudiante | U34: 0987570469 | V34: otro familiar | W34: 0958796689 | X34: Otro familiar | Y34: Unidad Educativa Manuela Espejo | Z34: 4o EGB | AA34: Hidrocefalia Congenita | AB34: NO
A35: 14 | B35: josueo1790@gmail.com | C35: 2o | D35: B (vespertina) | E35: Ortiz Arias | F35: Josué Alexander | G35: 1 | I35: contrabajo | J35: Vasquez Sánchez David Hernán | K35: 1851388833 | L35: 43038 | M35: 7 | N35: Arias Durán | O35: Gabriela Cecilia | P35: 1804024022 | Q35: Patate, sector Patate viejo, vía a Baños km 2 | S35: 0959235268 | T35: Madre del estudiante | U35: 0981289885 | V35: Padre | Y35: Escuela de Educación Básica Patate | Z35: 4o EGB | AA35: Asma | AB35: NO
A36: 15 | B36: infoparedesmarco@gmail.com | C36: 2o | D36: B (vespertina) | E36: Paredes Crespo | F36: Josué Antonio | G36: 1 | I36: piano | J36: Chicaiza Yánez Jefferson Alexander | K36: 1851318244 | L36: 42775 | M36: 8 | N36: Paredes Chicaiza | O36: Marco Antonio | P36: 1803929825 | Q36: Av Atahualpa y Los Incas Pasaje | R36: 032400024 | S36: 983403396 | T36: Padre del estudiante | U36: 0998921972 | V36: Madre | W36: 0939728916 | X36: Estudiante | Y36: Unidad educativa Ambato | Z36: 4o EGB | AB36: NO
A37: 16 | B37: ger_sanchez39@hotmail.com | C37: 2o | D37: B (vespertina) | E37: Pérez Sánchez | F37: Isabella Sofía | H37: 1 | I37: piano | J37: Erazo Moreno Carlos Efrén | K37: 1851372720 | L37: 42979 | M37: 8 | N37: Sánchez Sánchez | O37: Germania Cumandá | P37: 1803736188 | Q37: Avellanas No. 21 y las Limas | R37: 032513199 | S37: 0995940789 | T37: Madre del estudiante | U37: 0995910279 | V37: Padre | W37: 0984073807 | X37: Otro familiar | Y37: Unidad Educativa Santo Domingo de Guazmán | Z37: 4o EGB | AA37: Acaros | AB37: NO
A38: 17 | B38: daygav@hotmail.com | C38: 2o | D38: B (vespertina) | E38: Ruiz Gavilanez | F38: Martín Emiliano | G38: 1 | I38: violín | J38: Amores Valdivieso Jenny Natividad | K38: 1851442945 | L38: 43242 | M38: 7 | N38: Gavilanez Reyes | O38: Dayana Elizabeth | P38: 1804538955 | Q38: Cevallos y Vargas Torres | R38: 032825364 | S38: 987285810 | T38: Madre del estudiante | U38: 0998062567 | V38: otro familiar | Y38: San Isidro Labrador | Z38: 3o EGB | AA38: No | AB38: NO
A39: 18 | B39: veritocv_18@hotmail.com | C39: 2o | D39: B (vespertina) | E39: Salazar Córdova | F39: Mathías Andrés | G39: 1 | I39: piano | J39: Chicaiza Orozco Marcelo Javier | K39: 1851310571 | L39: 42739 | M39: 8 | N39: Córdova Vivas | O39: Verónica Alexandra | P39: 1804173449 | Q39: Parroquia picaihua calle Moisés Sánchez y los cipreses | S39: 0984717254 | T39: Madre del estudiante | U39: 0995676418 | V39: Padre | W39: 0984041635 | X39: Otro familiar | Y39: Unidad educativa Francisco Flor | Z39: 3o EGB | AA39: Presenta Rinitis alérgica | AB39: NO
A40: 19 | B40: pilita-chavez1994@hotmail.com | C40: 2o | D40: B (vespertina) | E40: Sánchez Chávez | F40: Ana Paula | H40: 1 | I40: viola | J40: Jiménez Vega Mauricio Marmonte | K40: 1851319184 | L40: 42776 | M40: 8 | N40: Chávez Supe | O40: Monica Del Pilar | P40: 1805523469 | Q40: Andiglata | R40: 032864505 | S40: 0962922928 | T40: Madre del estudiante | U40: 0984418127 | V40: Padre | W40: 0998700631 | X40: Estudiante | Y40: Conservatorio Bolivar | Z40: 2o EGB | AB40: NO
A41: 20 | B41: nelsonyanez1992@gmail.com | C41: 2o | D41: B (vespertina) | E41: Yanez Rivera | F41: Maykel Isdrael | G41: 1 | I41: saxofon | J41: Arevalo Catañeda Angel Jorge | K41: 1851382752 | L41: 43014 | M41: 7 | N41: Yanez Bombon | O41: Nelson Armando | P41: 1805330303 | Q41: Parroquia Atahualpa | R41: 0996395403 | S41: 0996395403 | T41: Padre del estudiante | U41: 0998043625 | V41: Padre | W41: 0995773167 | X41: Madre | Y41: U.E. ATAHUALPA | Z41: 4o EGB | AB41: NO
...

Sheet 3o
A1: No | B1: Dirección de correo electrónico | C1: Año de estudio | D1: PARALELO (señalar el mismo paralelo en el que estuvieron el año anterior) | E1: Apellidos del Estudiante | F1: Nombres del Estudiante | G1: M | H1: F | I1: Instrumento que estudia en el Conservatorio Bolívar | J1: Maestro de Instrumento | K1: Agrupación | L1: Fecha de Nacimiento del estudiante | M1: Edad del estudiante | N1: Apellidos del Representante del Estudiante | O1: Nombres del Representante del Estudiante | P1: Número de cédula del Representante | Q1: Dirección | R1: Número telefónico convencional | S1: Número telefónico celular 1 | T1: Número telefónico celular 1 pertenece a | U1: Número telefónico celular 2 | V1: Número celular 2 pertenece a | W1: Número telefónico celular 3 | X1: Número celular 3 pertenece a | Y1: Institución que estudia su formación regular | Z1: Año de Estudio en su formación Regular | AA1: ¿Existe alguna alergia/enfermedad/ condición del estudiante que la institución debe tener en cuenta durante clases? | AB1: Indique si su representado tiene alguna Necesidad Educativa no asociada a una discapacidad | AC1: Si respondió SI Indique cual es la necesidad educativa | AD1: Número de Cédula del Estudiante
A2: 1 | B2: alicia519.7148@gmail.com | C2: 3o | D2: A (matutina) | E2: Acosta Guamán | F2: Lucas Benjamín | G2: 1 | I2: Piano | J2: Solís Solís Juan Francisco | K2: Coro Matutino | L2: 42331 | M2: 9 | N2: Guaman Villacis | O2: Ibeth Alicia | P2: 1803578473 | Q2: Naranjillas y Guaytambos | S2: 099722002 | T2: Padre del estudiante | U2: 0988431247 | V2: Madre | W2: 0988431247 | X2: Madre | Y2: Homschooling | Z2: 5o EGB | AA2: Anemia, sangrados de nariz | AB2: NO
A3: 2 | B3: elymoretam2008@gmail.com | C3: 3o | D3: A (matutina) | E3: Aguilar Moreta | F3: Dylan Abiel | G3: 1 | I3: Saxofón | J3: Toapanta Arequipa Danny Alexander | K3: Orquesta matutina | L3: 42679 | M3: 8 | N3: Moreta Matsa | O3: Priscila Elizabeth | P3: 0999775513 | Q3: Miñarica 2 | R3: 032415801 | S3: 0999775513 | T3: Madre del estudiante | U3: 0979170913 | V3: otro familiar | W3: 0987766429 | X3: Padre | Y3: Unidad educativa Bolivar | Z3: 5o EGB | AA3: Colorantes y polvo | AB3: NO | AD3: 1851293165
A4: 3 | B4: losmensajeroskanito@hotmail.com | C4: 3o | D4: A (matutina) | E4: Caguana Yanchapanta | F4: Dulce Maria | H4: 1 | I4: Trompeta | J4: Amancha Hidalgo Félix Marcelo | K4: Orquesta matutina | L4: 42733 | M4: 8 | N4: Caguana Paucar | O4: Carlos Marcelo | P4: 1803567278 | Q4: Quisapincha | R4: 032772064 | S4: 0992541085 | T4: Padre del estudiante | U4: 0984218817 | V4: Madre | W4: 0961351050 | X4: otro familiar | Y4: Luis A. Martines | Z4: 5o EGB | AB4: NO | AD4: 1851315976
A5: 4 | B5: alex882023@hotmail.com | C5: 3o | D5: A (matutina) | E5: Cañar Machuca | F5: Christopher Ariel | G5: 1 | I5: Piano | J5: Quinapanta Tibán Angel Rodrigo | K5: Coro Matutino | L5: 42165 | M5: 10 | N5: Cañar Alarcón | O5: Darwin Alfredo | P5: 1803401536 | Q5: Eloy Alfaro y Bolivar | S5: 0993448933 | T5: Madre del estudiante | U5: 0939373957 | V5: Padre | W5: 0995000902 | X5: otro familiar | Y5: Unidad Educativa Bolivar | Z5: 6o EGB | AA5: Infección vías urinarias | AB5: NO | AD5: 1851163897
A6: 5 | B6: michelac80@hotmail.com | C6: 3o | D6: A (matutina) | E6: Coronel Cardenas | F6: Sol Maythe | H6: 1 | I6: Violín | J6: Jiménez Vega Mauricio Marmonte | K6: Orquesta matutina | L6: 42553 | M6: 9 | N6: Cardenas Palma | O6: Ivonne Mercedes | P6: 1803111192 | Q6: Huachi el Belén | R6: 0984009284 | S6: 0984009284 | T6: Madre del estudiante | U6: 0983532875 | V6: Padre | W6: 0983532875 | X6: Padre | Y6: Hispano America | Z6: 3o EGB | AB6: NO | AD6: 1851258358
A7: 6 | B7: pattyparedesjba@gmail.com | C7: 3o | D7: A (matutina) | E7: Cushpa Paredes | F7: Ángeles Daniela | H7: 1 | I7: Piano | J7: Solís Solís Juan Francisco | K7: Coro Matutino | L7: 42692 | M7: 8 | N7: Paredes Pimbo | O7: Patricia | P7: 1803625688 | Q7: Izamba | S7: 0983703545 | T7: Madre del estudiante | U7: 0984733797 | V7: Padre | W7: 0979026303 | X7: Estudiante | Y7: Unidad Educativa Juan Montalvo | Z7: 5o EGB | AB7: NO
A8: 7 | B8: jeanettealejo@hotmail.com | C8: 3o | D8: A (matutina) | E8: Hidalgo Escobar | F8: María Paz | H8: 1 | I8: Violín | J8: Jiménez Vega Mauricio Marmonte | K8: Orquesta matutina | L8: 42373 | M8: 9 | N8: Escobar Águila | O8: Elvia Jeanette | P8: 1804165593 | Q8: Huachi Grande, Barrio Gran Colombia. Calle Hawai y pasaje Idaho #83. A 2 cuadras de la gasolinera San Vicente. | R8: 032442053 | S8: 0984231024 | T8: Madre del estudiante | U8: 0995549043 | V8: otro familiar | W8: 0958744947 | X8: otro familiar | Y8: Unidad Educativa "Huachi Grande" | Z8: 5o EGB | AA8: Rinosinusitis aguda | AB8: NO
A9: 8 | B9: katymero1992@gmail.com | C9: 3o | D9: A (matutina) | E9: Iza mero | F9: Jesús Mathias | G9: 1 | I9: Piano | J9: Solís Solís Juan Francisco | K9: Coro Matutino | L9: 42340 | M9: 9 | N9: Mero Toalombo | O9: Katherin Lisbeth | P9: 1804831691 | Q9: Santa rosa | R9: 0995400424 | S9: 0995300424 | T9: Madre del estudiante | U9: 0991860928 | V9: Padre | W9: 0982687527 | X9: Estudiante | Y9: Mario cobo barona | Z9: 6o EGB | AA9: Posible caso de dixlecsia | AB9: SI | AC9: Posible caso de dixlecsia | AD9: 185119968-5
A10: 9 | B10: kleberlopez2012@hotmail.com | C10: 3o | D10: A (matutina) | E10: Lopez Andaluz | F10: Martin Alexander | G10: 1 | I10: Trompeta | J10: Amancha Hidalgo Félix Marcelo | K10: Orquesta matutina | L10: 42394 | M10: 9 | N10: Lopez Bonilla | O10: Kleber Martin | P10: 1803527157 | Q10: Sector Terremoto, paso lateral frente a los condominios "Alcala" | R10: 032763200 | S10: 0985414251 | T10: Padre del estudiante | U10: 0990821338 | V10: Madre | W10: 0999123660 | X10: otro familiar | Y10: Unidad Educativa "Guayaquil " | Z10: 5o EGB | AB10: NO
A11: 10 | B11: anitatituan225@gmail.com | C11: 3o | D11: A (matutina) | E11: Lozada Tituaña | F11: Samuel Benjamin | G11: 1 | I11: Trompeta | J11: Amancha Hidalgo Félix Marcelo | K11: Orquesta matutina | L11: 42488 | M11: 9 | N11: Tituaña Milan | O11: Ana Lucia | P11: 1802930121 | Q11: Av. Quito y 12 de Noviembre | S11: 0998513801 | T11: Madre del estudiante | U11: 0984518525 | V11: otro familiar | W11: 0968738158 | X11: otro familiar | Y11: Unidad Educativa Bolivar | Z11: 4o EGB | AB11: NO | AD11: 1851241230
A12: 11 | B12: villegaskrn300@gmail.com | C12: 3o | D12: A (matutina) | E12: Naranjo Meneses | F12: Scarlett Nahomi | H12: 1 | I12: Violín | J12: Jiménez Vega Mauricio Marmonte | K12: Orquesta matutina | L12: 42299 | M12: 9 | N12: Meneses Villegas | O12: Karen Ivonne | P12: 1804924650 | Q12: Huachi El Progreso | R12: 2408560 | S12: 0984478998 | T12: Madre del estudiante | U12: 0984209219 | V12: Padre | W12: 0983568488 | X12: otro familiar | Y12: Unidad Educativa Bolívar | Z12: 6o EGB | AB12: NO
A13: 12 | B13: minimarket.jv.quis@gmail.com | C13: 3o | D13: A (matutina) | E13: Olovacha Tubon | F13: José Andrés | G13: 1 | I13: Saxofón | J13: Toapanta Arequipa Danny Alexander | K13: Orquesta matutina | L13: 42522 | M13: 9 | N13: Olovacha Tubon | O13: Soraida Vanessa | P13: 0987517351 | Q13: Quisapincha barrio l centro | S13: 0984928053 | T13: Madre del estudiante | W13: 0999368290 | X13: otro familiar | Y13: Juan Montalvo | Z13: 5o EGB | AB13: NO
A14: 13 | B14: ximenamoposita@gmail.com | C14: 3o | D14: A (matutina) | E14: Pullutasig Moposita | F14: Mathias Jesús | G14: 1 | I14: Piano | J14: Quinapanta Tibán Angel Rodrigo | K14: Coro Matutino | L14: 42399 | M14: 9 | N14: MOPOSITA COCHA | O14: Ximena Alexandra | P14: 1803954724 | Q14: La Península | R14: 032445231 | S14: 09877978900 | T14: Madre del estudiante | U14: 0999015889 | V14: otro familiar | W14: 0 99 259 8648 | X14: otro familiar | Y14: U.E. Juan Montalvo | Z14: 5o EGB | AB14: NO | AD14: 1851216513
A15: 14 | B15: alexandraguaman833@gmail.com | C15: 3o | D15: A (matutina) | E15: Punina Guaman | F15: Adonis Jared | G15: 1 | I15: Saxofón | J15: Toapanta Arequipa Danny Alexander | K15: Orquesta matutina | L15: 42676 | M15: 8 | N15: Guaman Gavilanez | O15: Gabriela Alexandra | P15: 1804444337 | Q15: Alobamba | R15: 032754696 | S15: 978788131 | T15: Madre del estudiante | U15: 0996408671 | V15: otro familiar | W15: 000000000 | X15: otro familiar | Y15: Unidad Educativa Bolivar | Z15: 5o EGB | AD15: 1851292118
A16: 15 | B16: jq92406@gmail.com | C16: 3o | D16: A (matutina) | E16: Quispe Ayuquina | F16: Lourdes Ayme | H16: 1 | I16: Trompeta | J16: Amancha Hidalgo Félix Marcelo | K16: Orquesta matutina | L16: 42490 | M16: 9 | N16: Ayuquina Lagua | O16: Blanca Delfina | P16: 1803934437 | Q16: Caserio Lacon | S16: 986554152 | T16: Padre del estudiante | U16: 981114127 | V16: otro familiar | W16: 997578738 | X16: Madre | Y16: Unida Educativa Juan Benigno Vela | Z16: 5o EGB | AA16: No | AB16: NO | AD16: 1850486604
A17: 16 | B17: marisoltoasa.mt@gmail.com | C17: 3o | D17: A (matutina) | E17: Quispe Toasa | F17: Ian Gael | G17: 1 | I17: Violín | J17: Gutama Galan Juan Diego | K17: Orquesta matutina | L17: 42245 | M17: 9 | N17: Toasa Aldas | O17: Marisol Alejandra | P17: 1803582152 | Q17: Pinllo barrio Andiglata | R17: 000000 | S17: 0998786172 | T17: Madre del estudiante | U17: 0999571966 | V17: Padre | W17: 0986208010 | X17: otro familiar | Y17: Unidad Educativa Bolivar | Z17: 5o EGB | AB17: NO
A18: 17 | B18: santianaj78@gmail.com | C18: 3o | D18: A (matutina) | E18: Villacres Santiana | F18: Genesis Elizabeth | H18: 1 | I18: Piano | J18: Chicaiza Orozco Marcelo Javier | K18: Coro Matutino | L18: 42220 | M18: 9 | N18: Santiana Oñate | O18: Jessica Angélica | P18: 1805020748 | Q18: Mall de los Andes | S18: 998004351 | T18: Madre del estudiante | U18: 0983611858 | V18: otro familiar | W18: 0983880458 | X18: Estudiante | Y18: MARIO COBO BARONA | Z18: 6o EGB | AB18: NO | AD18: 1851185015
A19: 18 | B19: Christian_villalv@yahoo.com | C19: 3o | D19: B (vespertina) | E19: Villalva Pinto | F19: Diogo Alexander | G19: 1 | I19: Piano | J19: Pérez Toapanta Diego Armando | K19: Coro (estudiantes de piano) | L19: 42350 | M19: 9 | N19: Villalva González | O19: Christian Daniel | P19: 1804731840 | Q19: 1ra Imprenta y Tomás Sevilla | S19: 0998338462 | T19: Padre del estudiante | U19: 0983499992 | V19: otro familiar | W19: 0991856607 | X19: otro familiar | Y19: Pedro Fermín Cevallos | Z19: 6o EGB
G20: =SUM(G2:G19) -> 11 | H20: =SUM(H2:H18) -> 7
A22: No | B22: Dirección de correo electrónico | C22: Año de estudio | D22: PARALELO (señalar el mismo paralelo en el que estuvieron el año anterior) | E22: Apellidos del Estudiante | F22: Nombres del Estudiante | G22: M | H22: F | I22: Instrumento que estudia en el Conservatorio Bolívar | J22: Maestro de Instrumento | K22: Agrupación | L22: Fecha de Nacimiento del estudiante | M22: Edad del estudiante | N22: Apellidos del Representante del Estudiante | O22: Nombres del Representante del Estudiante | P22: Número de cédula del Representante | Q22: Dirección | R22: Número telefónico convencional | S22: Número telefónico celular 1 | T22: Número telefónico celular 1 pertenece a | U22: Número telefónico celular 2 | V22: Número celular 2 pertenece a | W22: Número telefónico celular 3 | X22: Número celular 3 pertenece a | Y22: Institución que estudia su formación regular | Z22: Año de Estudio en su formación Regular | AA22: ¿Existe alguna alergia/enfermedad/ condición del estudiante que la institución debe tener en cuenta durante clases? | AB22: Indique si su representado tiene alguna Necesidad Educativa no asociada a una discapacidad | AC22: Si respondió SI Indique cual es la necesidad educativa | AD22: Número de Cédula del Estudiante
A23: 1 | B23: lorecastilloch@gmail.com | C23: 3o | D23: B (vespertina) | E23: Altamirano Castillo | F23: Arelys Macarena | H23: 1 | I23: Violín | J23: Amores Valdivieso Jenny Natividad | K23: Orquesta de cuerdas frotadas (violín, viola, violonchelo, contrabajo) | L23: 42548 | M23: 9 | N23: Castillo Chaglla | O23: Lorena Ivonne | P23: 1803551355 | Q23: Av. Manuelita Saenz y Miguel de Cervantes | S23: 0987828603 | T23: Madre del estudiante | U23: 0992729102 | V23: Padre | W23: 0987828603 | X23: Madre | Y23: U. E. Santo Domingo de Guzmán Ambato | Z23: 5o EGB | AB23: NO | AD23: 1851257574
A24: 2 | B24: claudia_elizt@yahoo.com | C24: 3o | D24: B (vespertina) | E24: Amancha Montesdeoca | F24: Dylan Gael | G24: 1 | I24: Guitarra | J24: Chicaiza Cuenca Rubén Geovany | K24: Ensamble de guitarras | L24: 42727 | M24: 8 | N24: Montesdeoca Espin | O24: Claudia Elizabeth | P24: 1600299539 | Q24: Cdla España entre Málaga y Valencia | R24: 032415989 | S24: 0998553363 | T24: Madre del estudiante | U24: 0998757686 | V24: Padre | W24: 0998788906 | X24: otro familiar | Y24: UNIDAD EDUCATIVA GONZALEZ SUAREZ | Z24: 5o EGB | AB24: NO | AD24: 1851305514
A25: 3 | B25: luisdanielanilema@gmail.com | C25: 3o | D25: B (vespertina) | E25: Anilema Yuquilema | F25: Mathias Grabriel | G25: 1 | I25: Piano | J25: De la Cruz Changalombo Jorge Ramiro | K25: Coro (estudiantes de piano) | L25: 42444 | M25: 9 | N25: Anilema Guacho | O25: Luis | P25: 1804205068 | Q25: Av bolivariana y Cristóbal Ojeda | S25: 0991883904 | T25: Padre del estudiante | U25: 0994409433 | V25: Madre | W25: 0999175845 | X25: otro familiar | Y25: Luis A Martinez | Z25: 5o EGB | AD25: 1851237238
A26: 4 | B26: mischiquitinescdi@gmail.com | C26: 3o | D26: B (vespertina) | E26: Cevallos Gavilanes | F26: Santiago David | G26: 1 | I26: Piano | J26: Solís Solís Juan Francisco | K26: Coro (estudiantes de piano) | L26: 42248 | M26: 9 | N26: Cevallos Carrillo | O26: Freddy Santiago | P26: 1803047180 | Q26: Cdla. Oscus. Ortega Gasset y Delibes. Casa blanca con negro frente al parque infantil. Sector Paseo Shopping. | S26: 0998903816 | T26: Padre del estudiante | V26: Padre | W26: 0984056679 | X26: Madre | Y26: ACE School of tomorrow | Z26: 5o EGB | AB26: NO | AD26: 1851190809
A27: 5 | B27: patricia1992chicaiza@gmail.com | C27: 3o | D27: B (vespertina) | E27: Curillo Chipantiza | F27: Josue Aaron | G27: 1 | I27: Piano | J27: Caiza Caiza Roberto Carlos | K27: Coro (estudiantes de piano) | L27: 42469 | M27: 9 | N27: Chipantiza Chicaiza | O27: Blanca Patricia | P27: 1805295928 | Q27: Chambiato | R27: 0962606990 | S27: 0959856203 | T27: Madre del estudiante | U27: 0959856203 | V27: Madre | W27: 0962606990 | X27: otro familiar | Y27: U.E Gabriela Mistral | Z27: 4o EGB | AB27: NO
A28: 6 | B28: paulytorres2011@hotmail.com | C28: 3o | D28: B (vespertina) | E28: Ipiales Torres | F28: Marco Emilio | G28: 1 | I28: Guitarra | J28: Chicaiza Cuenca Rubén Geovany | K28: Ensamble de guitarras | L28: 42307 | M28: 9 | N28: Torres ALdaz | O28: Andrea Paulina | P28: 1804606208 | Q28: Huachi El Belén | R28: 2441106 | S28: 0980735187 | T28: Madre del estudiante | U28: 0994377652 | V28: Padre | W28: 0984717759 | X28: otro familiar | Y28: Manuela Espejo | Z28: 6o EGB | AB28: NO | AD28: 1851191765
A29: 7 | B29: juanys2404@gmail.com | C29: 3o | D29: B (vespertina) | E29: Morocho Chuqui | F29: Paula Thais | H29: 1 | I29: Guitarra | J29: Cumbicos Macas José Luis | K29: Ensamble de guitarras | L29: 45693 | M29: 9 | N29: Chuqui Guacho | O29: Juana | P29: 1803107885 | Q29: Av. Julio Jaramillo S/N y Pasaje Feraúd Guzmán | R29: 032511103 | S29: 0995765376 | T29: Madre del estudiante | U29: 0984030705 | V29: Padre | W29: 0981183839 | X29: otro familiar | Y29: Unidad Educativa Francisco Flor | Z29: 5o EGB | AA29: Alérgica a los colorantes | AB29: NO | AD29: 1851218469
A30: 8 | B30: david-mabe@hotmail.com | C30: 3o | D30: B (vespertina) | E30: Nuñez Chávez | F30: Martin David | G30: 1 | I30: Piano | J30: Solís Solís Juan Francisco | K30: Coro (estudiantes de piano) | L30: 42514 | M30: 9 | N30: Chávez Zambrano | O30: Bertha María | P30: 0201794195 | Q30: Macasto sector valle hermoso conjunto horizonte casa #87 | R30: 032511956 | S30: 0969940729 | T30: Madre del estudiante | U30: 0999833683 | V30: Padre | W30: 0959232071 | X30: otro familiar | Y30: UE Eduardo Reyes Naranjo | Z30: 5o EGB | AA30: Ninguna | AB30: NO | AC30: Sin novedad
A31: 9 | B31: wendy.simba.10@gmail.com | C31: 3o | D31: B (vespertina) | E31: Rios Simba | F31: Emiliana Hadasa | H31: 1 | I31: Violín | J31: Amores Valdivieso Jenny Natividad | K31: Orquesta de cuerdas frotadas (violín, viola, violonchelo, contrabajo) | L31: 42723 | M31: 8 | N31: Simba Chasipanta | O31: Wendy Simba | P31: 1723035125 | Q31: Ambato | S31: 0995254864 | T31: Madre del estudiante | U31: 0961180539 | V31: Padre | W31: 0962159109 | X31: otro familiar | Y31: Unidad Educativa La Merced | Z31: 5o EGB | AD31: 1757832884
A32: 10 | B32: silviaf.f1990@gmail.com | C32: 3o | D32: B (vespertina) | E32: Solis Jerez | F32: Jared Sebastián | G32: 1 | I32: Saxofón | J32: Arevalo Catañeda Angel Jorge | K32: Ensamble de vientos (saxofón, clarinete, trompeta, trombón) | L32: 42151 | M32: 10 | N32: Jerez Junta | O32: Silvia Fernanda | P32: 1804247466 | Q32: Av. Los Chasquis e Isidro Viteri | S32: 0998623812 | T32: Madre del estudiante | U32: 0987221588 | V32: Padre | W32: 0998623812 | X32: Madre | Y32: Unidad Educativa Bolívar | Z32: 6o EGB
A33: 11 | B33: alejandrabarona1992@gmail.com | C33: 3o | D33: B (vespertina) | E33: Tapia Barona | F33: Dana Sahyri | H33: 1 | I33: Percusión | J33: Tapia García Kevin Paúl | K33: Orquesta de cuerdas frotadas (violín, viola, violonchelo, contrabajo) | L33: 42046 | M33: 10 | N33: Barona Zurita | O33: Alejandra Dominique | P33: 1804505905 | Q33: Floreana y cerro negro | R33: 0 | S33: 0998674834 | T33: Madre del estudiante | U33: 0998233215 | V33: Padre | W33: 0962822271 | X33: otro familiar | Y33: Rumiñahui | Z33: 6o EGB | AB33: NO
A34: 12 | B34: josetipan@hotmail.com | C34: 3o | D34: B (vespertina) | E34: Tipán Chalán | F34: Josué Benjamín | G34: 1 | I34: Violín | J34: Amores Valdivieso Jenny Natividad | K34: Orquesta de cuerdas frotadas (violín, viola, violonchelo, contrabajo) | L34: 42497 | M34: 9 | N34: Tipán Chango | O34: Segundo José | P34: 1803010618 | Q34: Gonzales Suarez y Vicente Rocafuerte | R34: 032525621 | S34: 0995390760 | T34: Padre del estudiante | U34: 0980232932 | V34: Madre | W34: 0000000000 | X34: otro familiar | Y34: UE Juan León Mera - La Salle | Z34: 5o EGB | AA34: Ninguno | AB34: NO | AD34: 1851243954
A35: 13 | B35: carmita_isabel@yahoo.com | C35: 3o | D35: B (vespertina) | E35: Tipan Toalombo | F35: Alan Samuel | G35: 1 | I35: Violín | J35: Villena Cárdenas Maria Isabel | K35: Orquesta de cuerdas frotadas (violín, viola, violonchelo, contrabajo) | L35: 42285 | M35: 9 | N35: Toalombo Chicaiza | O35: Carmen Isabel | P35: 1804172854 | Q35: Ambato Parroquia Juan Benigno Vela | S35: 0939218085 | T35: Madre del estudiante | U35: 0957988856 | V35: Padre | W35: 0967988856 | X35: Padre | Y35: Unidad Educativa Luis .A .Martinez | Z35: 6o EGB | AB35: NO
A36: 14 | B36: coralejahermosa123@gmail.com | C36: 3o | D36: B (vespertina) | E36: Tustón Lucero | F36: Leandro Gael | G36: 1 | I36: Percusión | J36: Tapia García Kevin Paúl | K36: Orquesta de cuerdas frotadas (violín, viola, violonchelo, contrabajo) | L36: 42260 | M36: 10 | N36: Lucero | O36: Marcela | P36: 1804250932 | Q36: Pichincha alta y Cotopaxi | S36: 987492238 | T36: Madre del estudiante | U36: 995702577 | V36: otro familiar | W36: 987759947 | X36: otro familiar | Y36: González Suárez | Z36: 6o EGB | AB36: NO | AD36: 1851187029
A37: 15 | B37: loren26062012@gmail.com | C37: 3o | D37: B (vespertina) | E37: Valle Ortiz | F37: Ana Paula | H37: 1 | I37: Piano | J37: Acosta Zagal Karolina | K37: Coro (estudiantes de piano) | L37: 42705 | M37: 8 | N37: Ortiz Toscano | O37: Ligia Lorena | P37: 1804157467 | Q37: PSJ.JUAN ABEL ECHEVERRÍA Y GONZALO ESCUDERO | S37: 0984739236 | T37: Madre del estudiante | U37: 0987677823 | V37: otro familiar | W37: 0998597379 | X37: Padre | Y37: UK International School | Z37: 5o EGB | AA37: TDAH | AB37: SI | AC37: TDAH Transtorno de Deficit de atención con Hiperactividad moderada | AD37: 1757798622
G38: =SUM(G22:G37) -> 10 | H38: 5
